Workbook

Sheet Exportsammanfattning
B3: Det här dokumentet exporterades från Numbers. Varje tabell konverterades till ett Excel-kalkylblad. Alla andra objekt på varje kalkylblad i Numbers lades på olika kalkylblad. Var medveten om att formelberäkningar kan bli annorlunda i Excel.
B7: Namn på Numbers-blad | C7: Namn på Numbers-tabell | D7: Namn på Excel-kalkylblad
B9: Budget maj-dec 2026
C10: Tabell 1 | D10: Budget maj-dec 2026
B11: Inmatning
C12: Tabell 1 | D12: Inmatning
B13: Resultat
C14: Tabell 1 | D14: Resultat
B15: Hjälptabell
C16: Tabell 1 | D16: Hjälptabell

Sheet Budget maj-dec 2026
A1: NORC budget maj–december 2026
A2: Månadsbudget med intäkter, personalkostnader uppdelade på lön, arbetsgivaravgift, tjänstepension och försäkring, samt övriga kostnader. Procentsatser kan justeras per månad.
A4: Post | B4: Maj | C4: Juni | D4: Juli | E4: Augusti | F4: September | G4: Oktober | H4: November | I4: December | J4: Totalt | K4: Kommentar
A5: INTÄKTER
A6: SafeSpring | B6: 226000 | C6: 226000 | D6: 0 | E6: 226000 | F6: 226000 | G6: 226000 | H6: 226000 | I6: 226000 | J6: {=SUM(B6:I6)} | K6: Förifylld enligt instruktion: 250 000 kr/mån
A7: Accure | B7: 0 | C7: 40000 | D7: 0 | E7: 40000 | F7: 40000 | G7: 40000 | H7: 40000 | I7: 40000 | J7: {=SUM(B7:I7)} | K7: Förifylld enligt instruktion: 40 000 kr/mån
A8: Team Neusta | B8: 0 | C8: 0 | D8: 0 | E8: 0 | F8: 0 | G8: 0 | H8: 0 | I8: 0 | J8: {=SUM(B8:I8)} | K8: Fyll i månadsvärden vid behov
A9: Volvo Energy | B9: 0 | C9: 0 | D9: 0 | E9: 0 | F9: 0 | G9: 0 | H9: 0 | I9: 0 | J9: {=SUM(B9:I9)} | K9: Fyll i månadsvärden vid behov
A10: Buddy Energy | B10: 0 | C10: 0 | D10: 0 | E10: 0 | F10: 0 | G10: 0 | H10: 0 | I10: 0 | J10: {=SUM(B10:I10)} | K10: Fyll i månadsvärden vid behov
A11: Gausta | B11: 0 | C11: 0 | D11: 0 | E11: 0 | F11: 0 | G11: 0 | H11: 0 | I11: 0 | J11: {=SUM(B11:I11)} | K11: Fyll i månadsvärden vid behov
A12: Raoul | B12: 0 | C12: 0 | D12: 0 | E12: 0 | F12: 0 | G12: 0 | H12: 0 | I12: 0 | J12: {=SUM(B12:I12)} | K12: Fyll i månadsvärden vid behov
A13: MedChain | B13: 50000 | C13: 50000 | D13: 50000 | E13: 50000 | F13: 50000 | G13: 50000 | H13: 50000 | I13: 50000 | J13: {=SUM(B13:I13)} | K13: Förifylld enligt instruktion: 50 000 kr/mån
A14: Internetmedicin | B14: 0 | C14: 0 | D14: 0 | E14: 0 | F14: 0 | G14: 0 | H14: 0 | I14: 0 | J14: {=SUM(B14:I14)} | K14: Fyll i månadsvärden vid behov
A15: Fragus? | B15: 0 | C15: 0 | D15: 0 | E15: 0 | F15: 0 | G15: 0 | H15: 0 | I15: 0 | J15: {=SUM(B15:I15)} | K15: Fyll i månadsvärden vid behov
A16: Obenämnd kund 3 | B16: 0 | C16: 0 | D16: 0 | E16: 0 | F16: 0 | G16: 0 | H16: 0 | I16: 0 | J16: {=SUM(B16:I16)} | K16: Fyll i månadsvärden vid behov
A17: Summa intäkter | B17: {=SUM(B6:B16)} | C17: {=SUM(C6:C16)} | D17: {=SUM(D6:D16)} | E17: {=SUM(E6:E16)} | F17: {=SUM(F6:F16)} | G17: {=SUM(G6:G16)} | H17: {=SUM(H6:H16)} | I17: {=SUM(I6:I16)} | J17: {=SUM(B17:I17)}
A19: PERSONALKOSTNADER
A20: Arbetsgivaravgift % | B20: {='Inmatning'!$B$4} | C20: {='Inmatning'!$B$4} | D20: {='Inmatning'!$B$4} | E20: {='Inmatning'!$B$4} | F20: {='Inmatning'!$B$4} | G20: {='Inmatning'!$B$4} | H20: {='Inmatning'!$B$4} | I20: {='Inmatning'!$B$4} | J20: {=AVERAGE(B20:I20)} | K20: Central procentsats per månad för arbetsgivaravgift
A21: Tjänstepension % | B21: =AVERAGE('Inmatning'!$C$42:$C$47) | C21: =AVERAGE('Inmatning'!$C$42:$C$47) | D21: =AVERAGE('Inmatning'!$C$42:$C$47) | E21: =AVERAGE('Inmatning'!$C$42:$C$47) | F21: =AVERAGE('Inmatning'!$C$42:$C$47) | G21: =AVERAGE('Inmatning'!$C$42:$C$47) | H21: =AVERAGE('Inmatning'!$C$42:$C$47) | I21: =AVERAGE('Inmatning'!$C$42:$C$47) | J21: =AVERAGE(B21:I21) | K21: Genomsnitt av individuella pensionssatser i Inmatning
A22: Personalförsäkring % | B22: {='Inmatning'!$B$6} | C22: {='Inmatning'!$B$6} | D22: {='Inmatning'!$B$6} | E22: {='Inmatning'!$B$6} | F22: {='Inmatning'!$B$6} | G22: {='Inmatning'!$B$6} | H22: {='Inmatning'!$B$6} | I22: {='Inmatning'!$B$6} | J22: {=AVERAGE(B22:I22)} | K22: Central procentsats per månad för personalförsäkring
A24: Johan Sandersnäs – arbetsgrad % | B24: 0.2 | C24: 0.2 | D24: 0.5 | E24: 0.5 | F24: 0.8 | G24: 0.8 | H24: 0.8 | I24: 0.8 | J24: {=AVERAGE(B24:I24)} | K24: Arbetsgrad kan ändras per månad
A25: Johan Sandersnäs – bruttolön | B25: ='Inmatning'!$B$42*B24 | C25: ='Inmatning'!$B$42*C24 | D25: ='Inmatning'!$B$42*D24 | E25: ='Inmatning'!$B$42*E24 | F25: ='Inmatning'!$B$42*F24 | G25: ='Inmatning'!$B$42*G24 | H25: ='Inmatning'!$B$42*H24 | I25: ='Inmatning'!$B$42*I24 | J25: =SUM(B25:I25) | K25: Bruttolön hämtas från Inmatning × arbetsgrad; kan skrivas över
A26: Johan Sandersnäs – arbetsgivaravgift | B26: {=B25*B$20} | C26: {=C25*C$20} | D26: {=D25*D$20} | E26: {=E25*E$20} | F26: {=F25*F$20} | G26: {=G25*G$20} | H26: {=H25*H$20} | I26: {=I25*I$20} | J26: {=SUM(B26:I26)} | K26: Bruttolön × arbetsgivaravgift %
A27: Johan Sandersnäs – tjänstepension | B27: =B25*'Inmatning'!$C$42 | C27: =C25*'Inmatning'!$C$42 | D27: =D25*'Inmatning'!$C$42 | E27: =E25*'Inmatning'!$C$42 | F27: =F25*'Inmatning'!$C$42 | G27: =G25*'Inmatning'!$C$42 | H27: =H25*'Inmatning'!$C$42 | I27: =I25*'Inmatning'!$C$42 | J27: =SUM(B27:I27) | K27: Tjänstepension hämtas från individuell pensionssats; kan skrivas över
A28: Johan Sandersnäs – personalförsäkring | B28: {=B25*B$22} | C28: {=C25*C$22} | D28: {=D25*D$22} | E28: {=E25*E$22} | F28: {=F25*F$22} | G28: {=G25*G$22} | H28: {=H25*H$22} | I28: {=I25*I$22} | J28: {=SUM(B28:I28)} | K28: Bruttolön × personalförsäkring %
A29: Johan Sandersnäs – total personalkostnad | B29: {=SUM(B25:B28)} | C29: {=SUM(C25:C28)} | D29: {=SUM(D25:D28)} | E29: {=SUM(E25:E28)} | F29: {=SUM(F25:F28)} | G29: {=SUM(G25:G28)} | H29: {=SUM(H25:H28)} | I29: {=SUM(I25:I28)} | J29: {=SUM(B29:I29)} | K29: Summa lön + arbetsgivaravgift + pension + försäkring
A31: Anders Rasmusson – arbetsgrad % | B31: 0.7 | C31: 0.7 | D31: 0.7 | E31: 0.7 | F31: 0.8 | G31: 0.8 | H31: 0.8 | I31: 0.8 | J31: {=AVERAGE(B31:I31)} | K31: Arbetsgrad kan ändras per månad
A32: Anders Rasmusson – bruttolön | B32: ='Inmatning'!$B$43*B31 | C32: ='Inmatning'!$B$43*C31 | D32: ='Inmatning'!$B$43*D31 | E32: ='Inmatning'!$B$43*E31 | F32: ='Inmatning'!$B$43*F31 | G32: ='Inmatning'!$B$43*G31 | H32: ='Inmatning'!$B$43*H31 | I32: ='Inmatning'!$B$43*I31 | J32: =SUM(B32:I32) | K32: Bruttolön hämtas från Inmatning × arbetsgrad; kan skrivas över
A33: Anders Rasmusson – arbetsgivaravgift | B33: {=B32*B$20} | C33: {=C32*C$20} | D33: {=D32*D$20} | E33: {=E32*E$20} | F33: {=F32*F$20} | G33: {=G32*G$20} | H33: {=H32*H$20} | I33: {=I32*I$20} | J33: {=SUM(B33:I33)} | K33: Bruttolön × arbetsgivaravgift %
A34: Anders Rasmusson – tjänstepension | B34: =B32*'Inmatning'!$C$43 | C34: =C32*'Inmatning'!$C$43 | D34: =D32*'Inmatning'!$C$43 | E34: =E32*'Inmatning'!$C$43 | F34: =F32*'Inmatning'!$C$43 | G34: =G32*'Inmatning'!$C$43 | H34: =H32*'Inmatning'!$C$43 | I34: =I32*'Inmatning'!$C$43 | J34: =SUM(B34:I34) | K34: Tjänstepension hämtas från individuell pensionssats; kan skrivas över
A35: Anders Rasmusson – personalförsäkring | B35: {=B32*B$22} | C35: {=C32*C$22} | D35: {=D32*D$22} | E35: {=E32*E$22} | F35: {=F32*F$22} | G35: {=G32*G$22} | H35: {=H32*H$22} | I35: {=I32*I$22} | J35: {=SUM(B35:I35)} | K35: Bruttolön × personalförsäkring %
A36: Anders Rasmusson – total personalkostnad | B36: {=SUM(B32:B35)} | C36: {=SUM(C32:C35)} | D36: {=SUM(D32:D35)} | E36: {=SUM(E32:E35)} | F36: {=SUM(F32:F35)} | G36: {=SUM(G32:G35)} | H36: {=SUM(H32:H35)} | I36: {=SUM(I32:I35)} | J36: {=SUM(B36:I36)} | K36: Summa lön + arbetsgivaravgift + pension + försäkring
A38: David Kremer – arbetsgrad % | B38: 0.2 | C38: 0.2 | D38: 0.5 | E38: 0.5 | F38: 0.8 | G38: 0.8 | H38: 0.8 | I38: 0.8 | J38: {=AVERAGE(B38:I38)} | K38: Arbetsgrad kan ändras per månad
A39: David Kremer – bruttolön | B39: ='Inmatning'!$B$44*B38 | C39: ='Inmatning'!$B$44*C38 | D39: ='Inmatning'!$B$44*D38 | E39: ='Inmatning'!$B$44*E38 | F39: ='Inmatning'!$B$44*F38 | G39: ='Inmatning'!$B$44*G38 | H39: ='Inmatning'!$B$44*H38 | I39: ='Inmatning'!$B$44*I38 | J39: =SUM(B39:I39) | K39: Bruttolön hämtas från Inmatning × arbetsgrad; kan skrivas över
A40: David Kremer – arbetsgivaravgift | B40: {=B39*B$20} | C40: {=C39*C$20} | D40: {=D39*D$20} | E40: {=E39*E$20} | F40: {=F39*F$20} | G40: {=G39*G$20} | H40: {=H39*H$20} | I40: {=I39*I$20} | J40: {=SUM(B40:I40)} | K40: Bruttolön × arbetsgivaravgift %
A41: David Kremer – tjänstepension | B41: =B39*'Inmatning'!$C$44 | C41: =C39*'Inmatning'!$C$44 | D41: =D39*'Inmatning'!$C$44 | E41: =E39*'Inmatning'!$C$44 | F41: =F39*'Inmatning'!$C$44 | G41: =G39*'Inmatning'!$C$44 | H41: =H39*'Inmatning'!$C$44 | I41: =I39*'Inmatning'!$C$44 | J41: =SUM(B41:I41) | K41: Tjänstepension hämtas från individuell pensionssats; kan skrivas över
A42: David Kremer – personalförsäkring | B42: {=B39*B$22} | C42: {=C39*C$22} | D42: {=D39*D$22} | E42: {=E39*E$22} | F42: {=F39*F$22} | G42: {=G39*G$22} | H42: {=H39*H$22} | I42: {=I39*I$22} | J42: {=SUM(B42:I42)} | K42: Bruttolön × personalförsäkring %
A43: David Kremer – total personalkostnad | B43: {=SUM(B39:B42)} | C43: {=SUM(C39:C42)} | D43: {=SUM(D39:D42)} | E43: {=SUM(E39:E42)} | F43: {=SUM(F39:F42)} | G43: {=SUM(G39:G42)} | H43: {=SUM(H39:H42)} | I43: {=SUM(I39:I42)} | J43: {=SUM(B43:I43)} | K43: Summa lön + arbetsgivaravgift + pension + försäkring
A45: Magnus Lindau – arbetsgrad % | B45: 0.2 | C45: 0.7 | D45: 0.7 | E45: 0.7 | F45: 0.8 | G45: 0.8 | H45: 0.8 | I45: 0.8 | J45: {=AVERAGE(B45:I45)} | K45: Arbetsgrad kan ändras per månad
A46: Magnus Lindau – bruttolön | B46: ='Inmatning'!$B$45*B45 | C46: ='Inmatning'!$B$45*C45 | D46: ='Inmatning'!$B$45*D45 | E46: ='Inmatning'!$B$45*E45 | F46: ='Inmatning'!$B$45*F45 | G46: ='Inmatning'!$B$45*G45 | H46: ='Inmatning'!$B$45*H45 | I46: ='Inmatning'!$B$45*I45 | J46: =SUM(B46:I46) | K46: Bruttolön hämtas från Inmatning × arbetsgrad; kan skrivas över
...

Sheet Inmatning
A1: Parameter | B1: Värde | C1: Kommentar
A2: Teamstorlek | B2: 6 | C2: Antal heltider
A3: Bruttolön_per_månad | B3: 60000 | C3: kr/mån per person
A4: Arbetsgivaravgifts_sats | B4: 0.3142 | C4: 31,42 %
A5: Standard_tjänstepensions_sats | B5: 0.06 | C5: Standard om ingen individuell pensionssats anges
A6: Personalförsäkrings_sats | B6: 0.005 | C6: 0,5 % av bruttolön
A7: Företagsförsäkring_per_månad | B7: 2000 | C7: Företagsförsäkring (bas)
A8: Mobilabonnemang_per_lina | B8: 250 | C8: kr/mån
A9: Antal_telefonabonnemang | B9: {=B2} | C9: Som standard = Teamstorlek
A10: Internetabonnemang_kontor | B10: 0 | C10: kr/mån kontor ingår på The Yard
A11: Microsoft_365_per_licens | B11: 100 | C11: kr/licens/mån
A12: Microsoft_365_antal_licenser | B12: {=B2} | C12: Som standard = Teamstorlek
A13: Adobe_All_Apps_per_licens | B13: 1000 | C13: kr/licens/mån
A14: Adobe_All_Apps_antal_licenser | B14: 2 | C14: Antal platser initialt
A15: E_signering_per_månad | B15: 0 | C15: Startnivå
A16: Bokföring_fakturering_per_månad | B16: 400 | C16: Startpaket
A17: Projektstyrning_per_månad | B17: 0 | C17: Trello/Notion gratisnivå = 0
A18: Förbrukning_kaffe_print_städ_per_månad | B18: 0 | C18: Miniminivå ingår i The Yard
A19: Kontorshyra_per_månad | B19: 15000 | C19: Hyra kr/mån (ändra här)
A20: Laptop_enhetspris | B20: 0 | C20: kr/st
A21: Skärm_enhetspris | B21: 0 | C21: kr/st 27"
A22: Docka_enhetspris | B22: 0 | C22: kr/st
A23: Tangentbord_mus_enhetspris | B23: 0 | C23: kr/set
A24: Mobiltelefon_enhetspris | B24: 0 | C24: kr/st
... A37: Wilhelm_bruttolön_per_månad_gammal | B37: 35000 | C37: Ersatt av personaltabellen nedan
A40: PERSONAL - grunddata
A41: Anställd | B41: Bruttolön per månad | C41: Tjänstepension % | D41: Kommentar
A42: Johan Sandersnäs | B42: 60000 | C42: 0.06 | D42: Styr bruttolön och pension i budgetfliken
A43: Anders Rasmusson | B43: 60000 | C43: 0.06 | D43: Styr bruttolön och pension i budgetfliken
A44: David Kremer | B44: 60000 | C44: 0.06 | D44: Styr bruttolön och pension i budgetfliken
A45: Magnus Lindau | B45: 60000 | C45: 0.06 | D45: Styr bruttolön och pension i budgetfliken
A46: Wilhelm Johansson | B46: 35000 | C46: 0.06 | D46: Styr bruttolön och pension i budgetfliken
A47: Ingrid Kraappa | B47: 60000 | C47: 0.06 | D47: Styr bruttolön och pension i budgetfliken

Sheet Resultat
A1: Post | B1: Belopp (kr)
A2: PERSONAL (per månad)
A3: Bruttolöner | B3: =SUM('Inmatning'!B42:B47)
A4: Arbetsgivaravgifter | B4: =B3*'Inmatning'!B4
A5: Tjänstepension | B5: =SUMPRODUCT('Inmatning'!B42:B47,'Inmatning'!C42:C47)
A6: Personalförsäkringar | B6: =B3*'Inmatning'!B6
A7: Summa personal/mån | B7: =SUM(B3:B6)
A9: ABONNEMANG & MJUKVARA (per månad)
A10: Företagsförsäkring | B10: {='Inmatning'!B7}
A11: Mobilabonnemang | B11: {='Inmatning'!B8*'Inmatning'!B9}
A12: Internet (kontor) | B12: {='Inmatning'!B10}
A13: Microsoft 365 | B13: {='Inmatning'!B11*'Inmatning'!B12}
A14: Adobe Creative Cloud | B14: {='Inmatning'!B13*'Inmatning'!B14}
A15: E-signering | B15: {='Inmatning'!B15}
A16: Bokföring/Fakturering | B16: {='Inmatning'!B16}
A17: Projektstyrning | B17: {='Inmatning'!B17}
A18: Summa abonnemang & mjukvara/mån | B18: {=SUM(B10:B17)}
A20: LOKAL & DRIFT (per månad)
A21: Förbrukning/kaffe/print/städ | B21: {='Inmatning'!B18}
A22: Kontorshyra | B22: {='Inmatning'!B19}
A23: Summa lokal & drift/mån | B23: {=SUM(B21:B22)}
A25: SUBTOTAL OPEX (exkl. hyra) | B25: {=B7+B18+B21}
A26: Månadskostnad inkl. hyra (OPEX) | B26: {=B7+B18+B23}
A27: Årskostnad inkl. hyra (OPEX × 12) | B27: {=B26*12}
A29: CAPEX – Hårdvara & kontorsutrustning (engångs)
A30: Bärbara datorer | B30: {='Inmatning'!B20*'Inmatning'!B2}
A31: Skärmar 27" | B31: {='Inmatning'!B21*'Inmatning'!B2}
A32: Dockor | B32: {='Inmatning'!B22*'Inmatning'!B2}
A33: Tangentbord/mus | B33: {='Inmatning'!B23*'Inmatning'!B2}
A34: Mobiltelefoner | B34: {='Inmatning'!B24*'Inmatning'!B2}
A35: Skrivbord + stolar | B35: {='Inmatning'!B25*'Inmatning'!B2}
A36: Mötesbord/stolar | B36: {='Inmatning'!B26}
A37: Skrivare | B37: {='Inmatning'!B27}
A38: Smått & övrigt | B38: {='Inmatning'!B28}
A39: Summa CAPEX | B39: {=SUM(B30:B38)}
A40: Avskrivning (mån) | B40: {=B39/'Inmatning'!B29}
A42: All-in månad (OPEX inkl. hyra + avskrivning) | B42: {=B26+B40}
A43: Kostnad per person och månad | B43: {=B26/'Inmatning'!B2}
A44: Debiterbara timmar/pers/mån | B44: {='Inmatning'!B30*'Inmatning'!B31}
A45: Intern kostnad per debiterbar timme | B45: {=B26/('Inmatning'!B2*B44)}
...

Sheet Hjälptabell
A1: Månad | B1: Resultat P&L | C1: Ack. resultat P&L | D1: Kassaflöde | E1: Ack. kassaflöde
A2: Maj | B2: {='Budget maj-dec 2026'!B17-SUM('Budget maj-dec 2026'!B66,'Budget maj-dec 2026'!B79,'Budget maj-dec 2026'!B84,'Budget maj-dec 2026'!B87)} | C2: {=B2} | D2: {='Budget maj-dec 2026'!B17-SUM('Budget maj-dec 2026'!B66,'Budget maj-dec 2026'!B79,'Budget maj-dec 2026'!B84,'Budget maj-dec 2026'!B87)+'Budget maj-dec 2026'!B87-'Budget maj-dec 2026'!B88} | E2: {=D2}
A3: Juni | B3: {='Budget maj-dec 2026'!C17-SUM('Budget maj-dec 2026'!C66,'Budget maj-dec 2026'!C79,'Budget maj-dec 2026'!C84,'Budget maj-dec 2026'!C87)} | C3: {=C2+B3} | D3: {='Budget maj-dec 2026'!C17-SUM('Budget maj-dec 2026'!C66,'Budget maj-dec 2026'!C79,'Budget maj-dec 2026'!C84,'Budget maj-dec 2026'!C87)+'Budget maj-dec 2026'!C87-'Budget maj-dec 2026'!C88} | E3: {=E2+D3}
A4: Juli | B4: {='Budget maj-dec 2026'!D17-SUM('Budget maj-dec 2026'!D66,'Budget maj-dec 2026'!D79,'Budget maj-dec 2026'!D84,'Budget maj-dec 2026'!D87)} | C4: {=C3+B4} | D4: {='Budget maj-dec 2026'!D17-SUM('Budget maj-dec 2026'!D66,'Budget maj-dec 2026'!D79,'Budget maj-dec 2026'!D84,'Budget maj-dec 2026'!D87)+'Budget maj-dec 2026'!D87-'Budget maj-dec 2026'!D88} | E4: {=E3+D4}
A5: Augusti | B5: {='Budget maj-dec 2026'!E17-SUM('Budget maj-dec 2026'!E66,'Budget maj-dec 2026'!E79,'Budget maj-dec 2026'!E84,'Budget maj-dec 2026'!E87)} | C5: {=C4+B5} | D5: {='Budget maj-dec 2026'!E17-SUM('Budget maj-dec 2026'!E66,'Budget maj-dec 2026'!E79,'Budget maj-dec 2026'!E84,'Budget maj-dec 2026'!E87)+'Budget maj-dec 2026'!E87-'Budget maj-dec 2026'!E88} | E5: {=E4+D5}
A6: September | B6: {='Budget maj-dec 2026'!F17-SUM('Budget maj-dec 2026'!F66,'Budget maj-dec 2026'!F79,'Budget maj-dec 2026'!F84,'Budget maj-dec 2026'!F87)} | C6: {=C5+B6} | D6: {='Budget maj-dec 2026'!F17-SUM('Budget maj-dec 2026'!F66,'Budget maj-dec 2026'!F79,'Budget maj-dec 2026'!F84,'Budget maj-dec 2026'!F87)+'Budget maj-dec 2026'!F87-'Budget maj-dec 2026'!F88} | E6: {=E5+D6}
A7: Oktober | B7: {='Budget maj-dec 2026'!G17-SUM('Budget maj-dec 2026'!G66,'Budget maj-dec 2026'!G79,'Budget maj-dec 2026'!G84,'Budget maj-dec 2026'!G87)} | C7: {=C6+B7} | D7: {='Budget maj-dec 2026'!G17-SUM('Budget maj-dec 2026'!G66,'Budget maj-dec 2026'!G79,'Budget maj-dec 2026'!G84,'Budget maj-dec 2026'!G87)+'Budget maj-dec 2026'!G87-'Budget maj-dec 2026'!G88} | E7: {=E6+D7}
A8: November | B8: {='Budget maj-dec 2026'!H17-SUM('Budget maj-dec 2026'!H66,'Budget maj-dec 2026'!H79,'Budget maj-dec 2026'!H84,'Budget maj-dec 2026'!H87)} | C8: {=C7+B8} | D8: {='Budget maj-dec 2026'!H17-SUM('Budget maj-dec 2026'!H66,'Budget maj-dec 2026'!H79,'Budget maj-dec 2026'!H84,'Budget maj-dec 2026'!H87)+'Budget maj-dec 2026'!H87-'Budget maj-dec 2026'!H88} | E8: {=E7+D8}
A9: December | B9: {='Budget maj-dec 2026'!I17-SUM('Budget maj-dec 2026'!I66,'Budget maj-dec 2026'!I79,'Budget maj-dec 2026'!I84,'Budget maj-dec 2026'!I87)} | C9: {=C8+B9} | D9: {='Budget maj-dec 2026'!I17-SUM('Budget maj-dec 2026'!I66,'Budget maj-dec 2026'!I79,'Budget maj-dec 2026'!I84,'Budget maj-dec 2026'!I87)+'Budget maj-dec 2026'!I87-'Budget maj-dec 2026'!I88} | E9: {=E8+D9}
