Workbook

Sheet Budget maj-dec 2026
A1: NORC budget maj–december 2026
A2: Månadsbudget med intäkter, personalkostnader uppdelade på lön, arbetsgivaravgift, tjänstepension och försäkring, samt övriga kostnader. Procentsatser kan justeras per månad.
A4: Post | B4: Maj | C4: Juni | D4: Juli | E4: Augusti | F4: September | G4: Oktober | H4: November | I4: December | J4: Totalt | K4: Kommentar
A5: INTÄKTER
A6: SafeSpring | B6: 226000 | C6: 226000 | D6: 0 | E6: 226000 | F6: 226000 | G6: 226000 | H6: 226000 | I6: 226000 | J6: {=SUM(B6:I6)} | K6: Förifylld enligt instruktion: 250 000 kr/mån
A7: Accure | B7: 0 | C7: 40000 | D7: 0 | E7: 40000 | F7: 40000 | G7: 40000 | H7: 40000 | I7: 40000 | J7: {=SUM(B7:I7)} | K7: Förifylld enligt instruktion: 40 000 kr/mån
A8: Team Neusta | B8: 0 | C8: 0 | D8: 0 | E8: 0 | F8: 0 | G8: 0 | H8: 0 | I8: 0 | J8: {=SUM(B8:I8)} | K8: Fyll i månadsvärden vid behov
A9: Volvo Energy | B9: 0 | C9: 0 | D9: 0 | E9: 0 | F9: 0 | G9: 0 | H9: 0 | I9: 0 | J9: {=SUM(B9:I9)} | K9: Fyll i månadsvärden vid behov
A10: Buddy Energy | B10: 0 | C10: 0 | D10: 0 | E10: 0 | F10: 0 | G10: 0 | H10: 0 | I10: 0 | J10: {=SUM(B10:I10)} | K10: Fyll i månadsvärden vid behov
A11: Gausta | B11: 0 | C11: 0 | D11: 0 | E11: 0 | F11: 0 | G11: 0 | H11: 0 | I11: 0 | J11: {=SUM(B11:I11)} | K11: Fyll i månadsvärden vid behov
A12: Raoul | B12: 0 | C12: 0 | D12: 0 | E12: 0 | F12: 0 | G12: 0 | H12: 0 | I12: 0 | J12: {=SUM(B12:I12)} | K12: Fyll i månadsvärden vid behov
A13: MedChain | B13: 50000 | C13: 50000 | D13: 50000 | E13: 50000 | F13: 50000 | G13: 50000 | H13: 50000 | I13: 50000 | J13: {=SUM(B13:I13)} | K13: Förifylld enligt instruktion: 50 000 kr/mån
A14: Internetmedicin | B14: 0 | C14: 0 | D14: 0 | E14: 0 | F14: 0 | G14: 0 | H14: 0 | I14: 0 | J14: {=SUM(B14:I14)} | K14: Fyll i månadsvärden vid behov
A15: Fragus? | B15: 0 | C15: 0 | D15: 0 | E15: 0 | F15: 0 | G15: 0 | H15: 0 | I15: 0 | J15: {=SUM(B15:I15)} | K15: Fyll i månadsvärden vid behov
A16: Obenämnd kund 3 | B16: 0 | C16: 0 | D16: 0 | E16: 0 | F16: 0 | G16: 0 | H16: 0 | I16: 0 | J16: {=SUM(B16:I16)} | K16: Fyll i månadsvärden vid behov
A17: Summa intäkter | B17: {=SUM(B6:B16)} | C17: {=SUM(C6:C16)} | D17: {=SUM(D6:D16)} | E17: {=SUM(E6:E16)} | F17: {=SUM(F6:F16)} | G17: {=SUM(G6:G16)} | H17: {=SUM(H6:H16)} | I17: {=SUM(I6:I16)} | J17: {=SUM(B17:I17)}
A19: PERSONALKOSTNADER
A20: Arbetsgivaravgift % | B20: {='Inmatning'!$B$4} | C20: {='Inmatning'!$B$4} | D20: {='Inmatning'!$B$4} | E20: {='Inmatning'!$B$4} | F20: {='Inmatning'!$B$4} | G20: {='Inmatning'!$B$4} | H20: {='Inmatning'!$B$4} | I20: {='Inmatning'!$B$4} | J20: {=AVERAGE(B20:I20)} | K20: Central procentsats per månad för arbetsgivaravgift
A21: Tjänstepension % | B21: =AVERAGE('Inmatning'!$C$42:$C$47) | C21: =AVERAGE('Inmatning'!$C$42:$C$47) | D21: =AVERAGE('Inmatning'!$C$42:$C$47) | E21: =AVERAGE('Inmatning'!$C$42:$C$47) | F21: =AVERAGE('Inmatning'!$C$42:$C$47) | G21: =AVERAGE('Inmatning'!$C$42:$C$47) | H21: =AVERAGE('Inmatning'!$C$42:$C$47) | I21: =AVERAGE('Inmatning'!$C$42:$C$47) | J21: =AVERAGE(B21:I21) | K21: Genomsnitt av individuella pensionssatser i Inmatning
A22: Personalförsäkring % | B22: {='Inmatning'!$B$6} | C22: {='Inmatning'!$B$6} | D22: {='Inmatning'!$B$6} | E22: {='Inmatning'!$B$6} | F22: {='Inmatning'!$B$6} | G22: {='Inmatning'!$B$6} | H22: {='Inmatning'!$B$6} | I22: {='Inmatning'!$B$6} | J22: {=AVERAGE(B22:I22)} | K22: Central procentsats per månad för personalförsäkring
A24: Johan Sandersnäs – arbetsgrad % | B24: 0.2 | C24: 0.2 | D24: 0.5 | E24: 0.5 | F24: 0.8 | G24: 0.8 | H24: 0.8 | I24: 0.8 | J24: {=AVERAGE(B24:I24)} | K24: Arbetsgrad kan ändras per månad
A25: Johan Sandersnäs – bruttolön | B25: ='Inmatning'!$B$42*B24 | C25: ='Inmatning'!$B$42*C24 | D25: ='Inmatning'!$B$42*D24 | E25: ='Inmatning'!$B$42*E24 | F25: ='Inmatning'!$B$42*F24 | G25: ='Inmatning'!$B$42*G24 | H25: ='Inmatning'!$B$42*H24 | I25: ='Inmatning'!$B$42*I24 | J25: =SUM(B25:I25) | K25: Bruttolön hämtas från Inmatning × arbetsgrad; kan skrivas över
A26: Johan Sandersnäs – arbetsgivaravgift | B26: {=B25*B$20} | C26: {=C25*C$20} | D26: {=D25*D$20} | E26: {=E25*E$20} | F26: {=F25*F$20} | G26: {=G25*G$20} | H26: {=H25*H$20} | I26: {=I25*I$20} | J26: {=SUM(B26:I26)} | K26: Bruttolön × arbetsgivaravgift %
A27: Johan Sandersnäs – tjänstepension | B27: =B25*'Inmatning'!$C$42 | C27: =C25*'Inmatning'!$C$42 | D27: =D25*'Inmatning'!$C$42 | E27: =E25*'Inmatning'!$C$42 | F27: =F25*'Inmatning'!$C$42 | G27: =G25*'Inmatning'!$C$42 | H27: =H25*'Inmatning'!$C$42 | I27: =I25*'Inmatning'!$C$42 | J27: =SUM(B27:I27) | K27: Tjänstepension hämtas från individuell pensionssats; kan skrivas över
A28: Johan Sandersnäs – personalförsäkring | B28: {=B25*B$22} | C28: {=C25*C$22} | D28: {=D25*D$22} | E28: {=E25*E$22} | F28: {=F25*F$22} | G28: {=G25*G$22} | H28: {=H25*H$22} | I28: {=I25*I$22} | J28: {=SUM(B28:I28)} | K28: Bruttolön × personalförsäkring %
A29: Johan Sandersnäs – total personalkostnad | B29: {=SUM(B25:B28)} | C29: {=SUM(C25:C28)} | D29: {=SUM(D25:D28)} | E29: {=SUM(E25:E28)} | F29: {=SUM(F25:F28)} | G29: {=SUM(G25:G28)} | H29: {=SUM(H25:H28)} | I29: {=SUM(I25:I28)} | J29: {=SUM(B29:I29)} | K29: Summa lön + arbetsgivaravgift + pension + försäkring
A31: Anders Rasmusson – arbetsgrad % | B31: 0.7 | C31: 0.7 | D31: 0.7 | E31: 0.7 | F31: 0.8 | G31: 0.8 | H31: 0.8 | I31: 0.8 | J31: {=AVERAGE(B31:I31)} | K31: Arbetsgrad kan ändras per månad
A32: Anders Rasmusson – bruttolön | B32: ='Inmatning'!$B$43*B31 | C32: ='Inmatning'!$B$43*C31 | D32: ='Inmatning'!$B$43*D31 | E32: ='Inmatning'!$B$43*E31 | F32: ='Inmatning'!$B$43*F31 | G32: ='Inmatning'!$B$43*G31 | H32: ='Inmatning'!$B$43*H31 | I32: ='Inmatning'!$B$43*I31 | J32: =SUM(B32:I32) | K32: Bruttolön hämtas från Inmatning × arbetsgrad; kan skrivas över
A33: Anders Rasmusson – arbetsgivaravgift | B33: {=B32*B$20} | C33: {=C32*C$20} | D33: {=D32*D$20} | E33: {=E32*E$20} | F33: {=F32*F$20} | G33: {=G32*G$20} | H33: {=H32*H$20} | I33: {=I32*I$20} | J33: {=SUM(B33:I33)} | K33: Bruttolön × arbetsgivaravgift %
A34: Anders Rasmusson – tjänstepension | B34: =B32*'Inmatning'!$C$43 | C34: =C32*'Inmatning'!$C$43 | D34: =D32*'Inmatning'!$C$43 | E34: =E32*'Inmatning'!$C$43 | F34: =F32*'Inmatning'!$C$43 | G34: =G32*'Inmatning'!$C$43 | H34: =H32*'Inmatning'!$C$43 | I34: =I32*'Inmatning'!$C$43 | J34: =SUM(B34:I34) | K34: Tjänstepension hämtas från individuell pensionssats; kan skrivas över
A35: Anders Rasmusson – personalförsäkring | B35: {=B32*B$22} | C35: {=C32*C$22} | D35: {=D32*D$22} | E35: {=E32*E$22} | F35: {=F32*F$22} | G35: {=G32*G$22} | H35: {=H32*H$22} | I35: {=I32*I$22} | J35: {=SUM(B35:I35)} | K35: Bruttolön × personalförsäkring %
A36: Anders Rasmusson – total personalkostnad | B36: {=SUM(B32:B35)} | C36: {=SUM(C32:C35)} | D36: {=SUM(D32:D35)} | E36: {=SUM(E32:E35)} | F36: {=SUM(F32:F35)} | G36: {=SUM(G32:G35)} | H36: {=SUM(H32:H35)} | I36: {=SUM(I32:I35)} | J36: {=SUM(B36:I36)} | K36: Summa lön + arbetsgivaravgift + pension + försäkring
A38: David Kremer – arbetsgrad % | B38: 0.2 | C38: 0.2 | D38: 0.5 | E38: 0.5 | F38: 0.8 | G38: 0.8 | H38: 0.8 | I38: 0.8 | J38: {=AVERAGE(B38:I38)} | K38: Arbetsgrad kan ändras per månad
A39: David Kremer – bruttolön | B39: ='Inmatning'!$B$44*B38 | C39: ='Inmatning'!$B$44*C38 | D39: ='Inmatning'!$B$44*D38 | E39: ='Inmatning'!$B$44*E38 | F39: ='Inmatning'!$B$44*F38 | G39: ='Inmatning'!$B$44*G38 | H39: ='Inmatning'!$B$44*H38 | I39: ='Inmatning'!$B$44*I38 | J39: =SUM(B39:I39) | K39: Bruttolön hämtas från Inmatning × arbetsgrad; kan skrivas över
A40: David Kremer – arbetsgivaravgift | B40: {=B39*B$20} | C40: {=C39*C$20} | D40: {=D39*D$20} | E40: {=E39*E$20} | F40: {=F39*F$20} | G40: {=G39*G$20} | H40: {=H39*H$20} | I40: {=I39*I$20} | J40: {=SUM(B40:I40)} | K40: Bruttolön × arbetsgivaravgift %
A41: David Kremer – tjänstepension | B41: =B39*'Inmatning'!$C$44 | C41: =C39*'Inmatning'!$C$44 | D41: =D39*'Inmatning'!$C$44 | E41: =E39*'Inmatning'!$C$44 | F41: =F39*'Inmatning'!$C$44 | G41: =G39*'Inmatning'!$C$44 | H41: =H39*'Inmatning'!$C$44 | I41: =I39*'Inmatning'!$C$44 | J41: =SUM(B41:I41) | K41: Tjänstepension hämtas från individuell pensionssats; kan skrivas över
A42: David Kremer – personalförsäkring | B42: {=B39*B$22} | C42: {=C39*C$22} | D42: {=D39*D$22} | E42: {=E39*E$22} | F42: {=F39*F$22} | G42: {=G39*G$22} | H42: {=H39*H$22} | I42: {=I39*I$22} | J42: {=SUM(B42:I42)} | K42: Bruttolön × personalförsäkring %
A43: David Kremer – total personalkostnad | B43: {=SUM(B39:B42)} | C43: {=SUM(C39:C42)} | D43: {=SUM(D39:D42)} | E43: {=SUM(E39:E42)} | F43: {=SUM(F39:F42)} | G43: {=SUM(G39:G42)} | H43: {=SUM(H39:H42)} | I43: {=SUM(I39:I42)} | J43: {=SUM(B43:I43)} | K43: Summa lön + arbetsgivaravgift + pension + försäkring
A45: Magnus Lindau – arbetsgrad % | B45: 0.2 | C45: 0.7 | D45: 0.7 | E45: 0.7 | F45: 0.8 | G45: 0.8 | H45: 0.8 | I45: 0.8 | J45: {=AVERAGE(B45:I45)} | K45: Arbetsgrad kan ändras per månad
A46: Magnus Lindau – bruttolön | B46: ='Inmatning'!$B$45*B45 | C46: ='Inmatning'!$B$45*C45 | D46: ='Inmatning'!$B$45*D45 | E46: ='Inmatning'!$B$45*E45 | F46: ='Inmatning'!$B$45*F45 | G46: ='Inmatning'!$B$45*G45 | H46: ='Inmatning'!$B$45*H45 | I46: ='Inmatning'!$B$45*I45 | J46: =SUM(B46:I46) | K46: Bruttolön hämtas från Inmatning × arbetsgrad; kan skrivas över
...

Sheet Inmatning
A1: Parameter | B1: Värde | C1: Kommentar
A2: Teamstorlek | B2: 6 | C2: Antal heltider
A3: Bruttolön_per_månad | B3: 60000 | C3: kr/mån per person
A4: Arbetsgivaravgifts_sats | B4: 0.3142 | C4: 31,42 %
A5: Standard_tjänstepensions_sats | B5: 0.06 | C5: Standard om ingen individuell pensionssats anges
A6: Personalförsäkrings_sats | B6: 0.005 | C6: 0,5 % av bruttolön
A7: Företagsförsäkring_per_månad | B7: 2000 | C7: Företagsförsäkring (bas)
A8: Mobilabonnemang_per_lina | B8: 250 | C8: kr/mån
A9: Antal_telefonabonnemang | B9: {=B2} | C9: Som standard = Teamstorlek
A10: Internetabonnemang_kontor | B10: 0 | C10: kr/mån kontor ingår på The Yard
A11: Microsoft_365_per_licens | B11: 100 | C11: kr/licens/mån
A12: Microsoft_365_antal_licenser | B12: {=B2} | C12: Som standard = Teamstorlek
A13: Adobe_All_Apps_per_licens | B13: 1000 | C13: kr/licens/mån
A14: Adobe_All_Apps_antal_licenser | B14: 2 | C14: Antal platser initialt
A15: E_signering_per_månad | B15: 0 | C15: Startnivå
A16: Bokföring_fakturering_per_månad | B16: 400 | C16: Startpaket
A17: Projektstyrning_per_månad | B17: 0 | C17: Trello/Notion gratisnivå = 0
A18: Förbrukning_kaffe_print_städ_per_månad | B18: 0 | C18: Miniminivå ingår i The Yard
A19: Kontorshyra_per_månad | B19: 15000 | C19: Hyra kr/mån (ändra här)
A20: Laptop_enhetspris | B20: 0 | C20: kr/st
A21: Skärm_enhetspris | B21: 0 | C21: kr/st 27"
A22: Docka_enhetspris | B22: 0 | C22: kr/st
A23: Tangentbord_mus_enhetspris | B23: 0 | C23: kr/set
A24: Mobiltelefon_enhetspris | B24: 0 | C24: kr/st
... A37: Wilhelm_bruttolön_per_månad_gammal | B37: 35000 | C37: Ersatt av personaltabellen nedan
A40: PERSONAL - grunddata
A41: Anställd | B41: Bruttolön per månad | C41: Tjänstepension % | D41: Kommentar
A42: Johan Sandersnäs | B42: 60000 | C42: 0.06 | D42: Styr bruttolön och pension i budgetfliken
A43: Anders Rasmusson | B43: 60000 | C43: 0.06 | D43: Styr bruttolön och pension i budgetfliken
A44: David Kremer | B44: 60000 | C44: 0.06 | D44: Styr bruttolön och pension i budgetfliken
A45: Magnus Lindau | B45: 60000 | C45: 0.06 | D45: Styr bruttolön och pension i budgetfliken
A46: Wilhelm Johansson | B46: 35000 | C46: 0.06 | D46: Styr bruttolön och pension i budgetfliken
A47: Ingrid Kraappa | B47: 60000 | C47: 0.06 | D47: Styr bruttolön och pension i budgetfliken

Sheet Kassaflöde inmatning
A1: Kassaflöde - inmatningar
A3: Parameter | B3: Värde | C3: Kommentar
A4: Startkapital | B4: 0 | C4: Likvida medel vid periodens början
A5: Startskuld | B5: 0 | C5: Skuld vid periodens början, dras från ingående likviditet
A6: Moms_sats | B6: 0.25 | C6: Används för moms på kundfakturor och momspliktiga kostnader
A7: Momsredovisning | B7: Kvartalsvis | C7: Välj Månadsvis eller Kvartalsvis
A8: Arbetsgivaravgift_och_skatt_redovisning | B8: Månadsvis | C8: Välj Månadsvis eller Kvartalsvis
A9: Förfallodag_skatt_AG | B9: 12 | C9: Betalningsdag månaden/kvartalet efter löneperioden
A10: Fördröjning_skatt_AG_månader | B10: 1 | C10: Normalt 1 månad efter löneperiod
A11: Löneutbetalningsdag | B11: 25 | C11: Lön betalas den 25:e eller närmast föregående vardag
A12: Andel_bruttolön_som_betalas_som_lön | B12: 1 | C12: 1,0 innebär att modellens bruttolön används som kassautbetalning
A13: Personal_skatt_%_på_bruttolön | B13: 0 | C13: Kan användas om personalskatt ska betalas separat utöver arbetsgivaravgift
A14: Månadsamortering_startskuld | B14: 0 | C14: Frivillig amortering på startskuld
A17: Kundbetalningar
A18: Kund | B18: Budgetrad | C18: Betalningsdagar | D18: Beräkna från | E18: Momspliktig | F18: Kommentar
A19: SafeSpring | B19: 6 | C19: 30 | D19: Månadsslut | E19: Ja | F19: Ändra till 60 dagar eller Fakturadatum vid behov
A20: Accure | B20: 7 | C20: 30 | D20: Månadsslut | E20: Ja | F20: Ändra till 60 dagar eller Fakturadatum vid behov
A21: Team Neusta | B21: 8 | C21: 30 | D21: Månadsslut | E21: Ja | F21: Ändra till 60 dagar eller Fakturadatum vid behov
A22: Volvo Energy | B22: 9 | C22: 30 | D22: Månadsslut | E22: Ja | F22: Ändra till 60 dagar eller Fakturadatum vid behov
A23: Buddy Energy | B23: 10 | C23: 30 | D23: Månadsslut | E23: Ja | F23: Ändra till 60 dagar eller Fakturadatum vid behov
A24: Gausta | B24: 11 | C24: 30 | D24: Månadsslut | E24: Ja | F24: Ändra till 60 dagar eller Fakturadatum vid behov
A25: Raoul | B25: 12 | C25: 30 | D25: Månadsslut | E25: Ja | F25: Ändra till 60 dagar eller Fakturadatum vid behov
A26: MedChain | B26: 13 | C26: 30 | D26: Månadsslut | E26: Ja | F26: Ändra till 60 dagar eller Fakturadatum vid behov
A27: Internetmedicin | B27: 14 | C27: 30 | D27: Månadsslut | E27: Ja | F27: Ändra till 60 dagar eller Fakturadatum vid behov
A28: Fragus? | B28: 15 | C28: 30 | D28: Månadsslut | E28: Ja | F28: Ändra till 60 dagar eller Fakturadatum vid behov
A29: Obenämnd kund 3 | B29: 16 | C29: 30 | D29: Månadsslut | E29: Ja | F29: Ändra till 60 dagar eller Fakturadatum vid behov
A33: Kostnader och förfallon
A34: Kostnad | B34: Budgetrad | C34: Frekvens | D34: Förfallodag | E34: Förfallomånad nr | F34: Momspliktig | G34: Belopp från | H34: Kommentar
A35: Adobe Creative Suite | B35: 69 | C35: Månadsvis | D35: 25 | E35: 5 | F35: Ja | G35: Budget maj-dec 2026 | H35: Frekvens styr när budgeterad månadskostnad betalas
A36: Google Workspace | B36: 70 | C36: Månadsvis | D36: 25 | E36: 5 | F36: Ja | G36: Budget maj-dec 2026 | H36: Frekvens styr när budgeterad månadskostnad betalas
A37: AI bildredigeringsprogram | B37: 71 | C37: Månadsvis | D37: 25 | E37: 5 | F37: Ja | G37: Budget maj-dec 2026 | H37: Frekvens styr när budgeterad månadskostnad betalas
A38: AI videoredigeringsprogram | B38: 72 | C38: Månadsvis | D38: 25 | E38: 5 | F38: Ja | G38: Budget maj-dec 2026 | H38: Frekvens styr när budgeterad månadskostnad betalas
A39: Företagsförsäkring | B39: 73 | C39: Årsvis | D39: 31 | E39: 5 | F39: Nej | G39: Budget maj-dec 2026 | H39: Frekvens styr när budgeterad månadskostnad betalas
A40: Representation | B40: 75 | C40: Månadsvis | D40: 25 | E40: 5 | F40: Ja | G40: Budget maj-dec 2026 | H40: Frekvens styr när budgeterad månadskostnad betalas
A41: Telefonabbonemang | B41: 76 | C41: Månadsvis | D41: 25 | E41: 5 | F41: Ja | G41: Budget maj-dec 2026 | H41: Frekvens styr när budgeterad månadskostnad betalas
A42: Bokföring/Fakturering | B42: 77 | C42: Månadsvis | D42: 25 | E42: 5 | F42: Ja | G42: Budget maj-dec 2026 | H42: Frekvens styr när budgeterad månadskostnad betalas
A43: Projektstyrning | B43: 78 | C43: Månadsvis | D43: 25 | E43: 5 | F43: Ja | G43: Budget maj-dec 2026 | H43: Frekvens styr när budgeterad månadskostnad betalas
A44: Kontorshyra | B44: 82 | C44: Månadsvis | D44: 25 | E44: 5 | F44: Nej | G44: Budget maj-dec 2026 | H44: Frekvens styr när budgeterad månadskostnad betalas
A45: Förbrukning/kaffe/print/städ | B45: 83 | C45: Månadsvis | D45: 25 | E45: 5 | F45: Ja | G45: Budget maj-dec 2026 | H45: Frekvens styr när budgeterad månadskostnad betalas
A46: Engångsinvestering hårdvara | B46: 88 | C46: Månadsvis | D46: 25 | E46: 5 | F46: Ja | G46: Budget maj-dec 2026 | H46: Frekvens styr när budgeterad månadskostnad betalas

Sheet Likviditet
A1: Kassaflöde och likviditet
B3: 46143 | C3: 46174 | D3: 46204 | E3: 46235 | F3: 46266 | G3: 46296 | H3: 46327 | I3: 46357
A5: Ingående likviditet | B5: ='Kassaflöde inmatning'!$B$4-'Kassaflöde inmatning'!$B$5 | C5: =B20 | D5: =C20 | E5: =D20 | F5: =E20 | G5: =F20 | H5: =G20 | I5: =H20
A7: Kundinbetalningar exkl. moms | B7: =SUMIFS('Kassaflöde beräkning'!$C$4:$C$91,'Kassaflöde beräkning'!$H$4:$H$91,B$3) | C7: =SUMIFS('Kassaflöde beräkning'!$C$4:$C$91,'Kassaflöde beräkning'!$H$4:$H$91,C$3) | D7: =SUMIFS('Kassaflöde beräkning'!$C$4:$C$91,'Kassaflöde beräkning'!$H$4:$H$91,D$3) | E7: =SUMIFS('Kassaflöde beräkning'!$C$4:$C$91,'Kassaflöde beräkning'!$H$4:$H$91,E$3) | F7: =SUMIFS('Kassaflöde beräkning'!$C$4:$C$91,'Kassaflöde beräkning'!$H$4:$H$91,F$3) | G7: =SUMIFS('Kassaflöde beräkning'!$C$4:$C$91,'Kassaflöde beräkning'!$H$4:$H$91,G$3) | H7: =SUMIFS('Kassaflöde beräkning'!$C$4:$C$91,'Kassaflöde beräkning'!$H$4:$H$91,H$3) | I7: =SUMIFS('Kassaflöde beräkning'!$C$4:$C$91,'Kassaflöde beräkning'!$H$4:$H$91,I$3)
A8: Moms från kundinbetalningar | B8: =SUMIFS('Kassaflöde beräkning'!$D$4:$D$91,'Kassaflöde beräkning'!$H$4:$H$91,B$3) | C8: =SUMIFS('Kassaflöde beräkning'!$D$4:$D$91,'Kassaflöde beräkning'!$H$4:$H$91,C$3) | D8: =SUMIFS('Kassaflöde beräkning'!$D$4:$D$91,'Kassaflöde beräkning'!$H$4:$H$91,D$3) | E8: =SUMIFS('Kassaflöde beräkning'!$D$4:$D$91,'Kassaflöde beräkning'!$H$4:$H$91,E$3) | F8: =SUMIFS('Kassaflöde beräkning'!$D$4:$D$91,'Kassaflöde beräkning'!$H$4:$H$91,F$3) | G8: =SUMIFS('Kassaflöde beräkning'!$D$4:$D$91,'Kassaflöde beräkning'!$H$4:$H$91,G$3) | H8: =SUMIFS('Kassaflöde beräkning'!$D$4:$D$91,'Kassaflöde beräkning'!$H$4:$H$91,H$3) | I8: =SUMIFS('Kassaflöde beräkning'!$D$4:$D$91,'Kassaflöde beräkning'!$H$4:$H$91,I$3)
A9: Kundinbetalningar inkl. moms | B9: =SUM(B7:B8) | C9: =SUM(C7:C8) | D9: =SUM(D7:D8) | E9: =SUM(E7:E8) | F9: =SUM(F7:F8) | G9: =SUM(G7:G8) | H9: =SUM(H7:H8) | I9: =SUM(I7:I8)
A11: Löneutbetalningar | B11: =SUMIFS('Kassaflöde beräkning'!$C$194:$C$209,'Kassaflöde beräkning'!$A$194:$A$209,"Lön",'Kassaflöde beräkning'!$E$194:$E$209,B$3) | C11: =SUMIFS('Kassaflöde beräkning'!$C$194:$C$209,'Kassaflöde beräkning'!$A$194:$A$209,"Lön",'Kassaflöde beräkning'!$E$194:$E$209,C$3) | D11: =SUMIFS('Kassaflöde beräkning'!$C$194:$C$209,'Kassaflöde beräkning'!$A$194:$A$209,"Lön",'Kassaflöde beräkning'!$E$194:$E$209,D$3) | E11: =SUMIFS('Kassaflöde beräkning'!$C$194:$C$209,'Kassaflöde beräkning'!$A$194:$A$209,"Lön",'Kassaflöde beräkning'!$E$194:$E$209,E$3) | F11: =SUMIFS('Kassaflöde beräkning'!$C$194:$C$209,'Kassaflöde beräkning'!$A$194:$A$209,"Lön",'Kassaflöde beräkning'!$E$194:$E$209,F$3) | G11: =SUMIFS('Kassaflöde beräkning'!$C$194:$C$209,'Kassaflöde beräkning'!$A$194:$A$209,"Lön",'Kassaflöde beräkning'!$E$194:$E$209,G$3) | H11: =SUMIFS('Kassaflöde beräkning'!$C$194:$C$209,'Kassaflöde beräkning'!$A$194:$A$209,"Lön",'Kassaflöde beräkning'!$E$194:$E$209,H$3) | I11: =SUMIFS('Kassaflöde beräkning'!$C$194:$C$209,'Kassaflöde beräkning'!$A$194:$A$209,"Lön",'Kassaflöde beräkning'!$E$194:$E$209,I$3)
A12: Leverantörsbetalningar exkl. moms | B12: =SUMIFS('Kassaflöde beräkning'!$C$95:$C$190,'Kassaflöde beräkning'!$I$95:$I$190,B$3) | C12: =SUMIFS('Kassaflöde beräkning'!$C$95:$C$190,'Kassaflöde beräkning'!$I$95:$I$190,C$3) | D12: =SUMIFS('Kassaflöde beräkning'!$C$95:$C$190,'Kassaflöde beräkning'!$I$95:$I$190,D$3) | E12: =SUMIFS('Kassaflöde beräkning'!$C$95:$C$190,'Kassaflöde beräkning'!$I$95:$I$190,E$3) | F12: =SUMIFS('Kassaflöde beräkning'!$C$95:$C$190,'Kassaflöde beräkning'!$I$95:$I$190,F$3) | G12: =SUMIFS('Kassaflöde beräkning'!$C$95:$C$190,'Kassaflöde beräkning'!$I$95:$I$190,G$3) | H12: =SUMIFS('Kassaflöde beräkning'!$C$95:$C$190,'Kassaflöde beräkning'!$I$95:$I$190,H$3) | I12: =SUMIFS('Kassaflöde beräkning'!$C$95:$C$190,'Kassaflöde beräkning'!$I$95:$I$190,I$3)
A13: Moms på leverantörsbetalningar | B13: =SUMIFS('Kassaflöde beräkning'!$D$95:$D$190,'Kassaflöde beräkning'!$I$95:$I$190,B$3) | C13: =SUMIFS('Kassaflöde beräkning'!$D$95:$D$190,'Kassaflöde beräkning'!$I$95:$I$190,C$3) | D13: =SUMIFS('Kassaflöde beräkning'!$D$95:$D$190,'Kassaflöde beräkning'!$I$95:$I$190,D$3) | E13: =SUMIFS('Kassaflöde beräkning'!$D$95:$D$190,'Kassaflöde beräkning'!$I$95:$I$190,E$3) | F13: =SUMIFS('Kassaflöde beräkning'!$D$95:$D$190,'Kassaflöde beräkning'!$I$95:$I$190,F$3) | G13: =SUMIFS('Kassaflöde beräkning'!$D$95:$D$190,'Kassaflöde beräkning'!$I$95:$I$190,G$3) | H13: =SUMIFS('Kassaflöde beräkning'!$D$95:$D$190,'Kassaflöde beräkning'!$I$95:$I$190,H$3) | I13: =SUMIFS('Kassaflöde beräkning'!$D$95:$D$190,'Kassaflöde beräkning'!$I$95:$I$190,I$3)
A14: Skatter och arbetsgivaravgifter | B14: =SUMIFS('Kassaflöde beräkning'!$C$194:$C$209,'Kassaflöde beräkning'!$A$194:$A$209,"Skatt och AG",'Kassaflöde beräkning'!$E$194:$E$209,B$3) | C14: =SUMIFS('Kassaflöde beräkning'!$C$194:$C$209,'Kassaflöde beräkning'!$A$194:$A$209,"Skatt och AG",'Kassaflöde beräkning'!$E$194:$E$209,C$3) | D14: =SUMIFS('Kassaflöde beräkning'!$C$194:$C$209,'Kassaflöde beräkning'!$A$194:$A$209,"Skatt och AG",'Kassaflöde beräkning'!$E$194:$E$209,D$3) | E14: =SUMIFS('Kassaflöde beräkning'!$C$194:$C$209,'Kassaflöde beräkning'!$A$194:$A$209,"Skatt och AG",'Kassaflöde beräkning'!$E$194:$E$209,E$3) | F14: =SUMIFS('Kassaflöde beräkning'!$C$194:$C$209,'Kassaflöde beräkning'!$A$194:$A$209,"Skatt och AG",'Kassaflöde beräkning'!$E$194:$E$209,F$3) | G14: =SUMIFS('Kassaflöde beräkning'!$C$194:$C$209,'Kassaflöde beräkning'!$A$194:$A$209,"Skatt och AG",'Kassaflöde beräkning'!$E$194:$E$209,G$3) | H14: =SUMIFS('Kassaflöde beräkning'!$C$194:$C$209,'Kassaflöde beräkning'!$A$194:$A$209,"Skatt och AG",'Kassaflöde beräkning'!$E$194:$E$209,H$3) | I14: =SUMIFS('Kassaflöde beräkning'!$C$194:$C$209,'Kassaflöde beräkning'!$A$194:$A$209,"Skatt och AG",'Kassaflöde beräkning'!$E$194:$E$209,I$3)
A15: Momsbetalning | B15: =IF('Kassaflöde inmatning'!$B$7="Månadsvis",0,0) | C15: =IF('Kassaflöde inmatning'!$B$7="Månadsvis",B22,IF(MONTH(C$3)=7,SUM(B22:C22),IF(MONTH(C$3)=10,SUM(D22:F22),0))) | D15: =IF('Kassaflöde inmatning'!$B$7="Månadsvis",C22,IF(MONTH(D$3)=7,SUM(B22:C22),IF(MONTH(D$3)=10,SUM(D22:F22),0))) | E15: =IF('Kassaflöde inmatning'!$B$7="Månadsvis",D22,IF(MONTH(E$3)=7,SUM(B22:C22),IF(MONTH(E$3)=10,SUM(D22:F22),0))) | F15: =IF('Kassaflöde inmatning'!$B$7="Månadsvis",E22,IF(MONTH(F$3)=7,SUM(B22:C22),IF(MONTH(F$3)=10,SUM(D22:F22),0))) | G15: =IF('Kassaflöde inmatning'!$B$7="Månadsvis",F22,IF(MONTH(G$3)=7,SUM(B22:C22),IF(MONTH(G$3)=10,SUM(D22:F22),0))) | H15: =IF('Kassaflöde inmatning'!$B$7="Månadsvis",G22,IF(MONTH(H$3)=7,SUM(B22:C22),IF(MONTH(H$3)=10,SUM(D22:F22),0))) | I15: =IF('Kassaflöde inmatning'!$B$7="Månadsvis",H22,IF(MONTH(I$3)=7,SUM(B22:C22),IF(MONTH(I$3)=10,SUM(D22:F22),0)))
A16: Amortering startskuld | B16: ='Kassaflöde inmatning'!$B$14 | C16: ='Kassaflöde inmatning'!$B$14 | D16: ='Kassaflöde inmatning'!$B$14 | E16: ='Kassaflöde inmatning'!$B$14 | F16: ='Kassaflöde inmatning'!$B$14 | G16: ='Kassaflöde inmatning'!$B$14 | H16: ='Kassaflöde inmatning'!$B$14 | I16: ='Kassaflöde inmatning'!$B$14
A17: Summa utbetalningar | B17: =SUM(B11:B16) | C17: =SUM(C11:C16) | D17: =SUM(D11:D16) | E17: =SUM(E11:E16) | F17: =SUM(F11:F16) | G17: =SUM(G11:G16) | H17: =SUM(H11:H16) | I17: =SUM(I11:I16)
A19: Månadens kassaflöde | B19: =B9-B17 | C19: =C9-C17 | D19: =D9-D17 | E19: =E9-E17 | F19: =F9-F17 | G19: =G9-G17 | H19: =H9-H17 | I19: =I9-I17
A20: Utgående likviditet | B20: =B5+B19 | C20: =C5+C19 | D20: =D5+D19 | E20: =E5+E19 | F20: =F5+F19 | G20: =G5+G19 | H20: =H5+H19 | I20: =I5+I19
A22: Netto moms genererad i månaden | B22: ='Budget maj-dec 2026'!B17*'Kassaflöde inmatning'!$B$6-SUMIFS('Kassaflöde beräkning'!$D$95:$D$190,'Kassaflöde beräkning'!$B$95:$B$190,B$3) | C22: ='Budget maj-dec 2026'!C17*'Kassaflöde inmatning'!$B$6-SUMIFS('Kassaflöde beräkning'!$D$95:$D$190,'Kassaflöde beräkning'!$B$95:$B$190,C$3) | D22: ='Budget maj-dec 2026'!D17*'Kassaflöde inmatning'!$B$6-SUMIFS('Kassaflöde beräkning'!$D$95:$D$190,'Kassaflöde beräkning'!$B$95:$B$190,D$3) | E22: ='Budget maj-dec 2026'!E17*'Kassaflöde inmatning'!$B$6-SUMIFS('Kassaflöde beräkning'!$D$95:$D$190,'Kassaflöde beräkning'!$B$95:$B$190,E$3) | F22: ='Budget maj-dec 2026'!F17*'Kassaflöde inmatning'!$B$6-SUMIFS('Kassaflöde beräkning'!$D$95:$D$190,'Kassaflöde beräkning'!$B$95:$B$190,F$3) | G22: ='Budget maj-dec 2026'!G17*'Kassaflöde inmatning'!$B$6-SUMIFS('Kassaflöde beräkning'!$D$95:$D$190,'Kassaflöde beräkning'!$B$95:$B$190,G$3) | H22: ='Budget maj-dec 2026'!H17*'Kassaflöde inmatning'!$B$6-SUMIFS('Kassaflöde beräkning'!$D$95:$D$190,'Kassaflöde beräkning'!$B$95:$B$190,H$3) | I22: ='Budget maj-dec 2026'!I17*'Kassaflöde inmatning'!$B$6-SUMIFS('Kassaflöde beräkning'!$D$95:$D$190,'Kassaflöde beräkning'!$B$95:$B$190,I$3)
A23: Skatt/AG som förfaller efter december | B23: =SUMIFS('Kassaflöde beräkning'!$C$194:$C$209,'Kassaflöde beräkning'!$A$194:$A$209,"Skatt och AG",'Kassaflöde beräkning'!$E$194:$E$209,">"&$I$3) | C23: =SUMIFS('Kassaflöde beräkning'!$C$194:$C$209,'Kassaflöde beräkning'!$A$194:$A$209,"Skatt och AG",'Kassaflöde beräkning'!$E$194:$E$209,">"&$I$3) | D23: =SUMIFS('Kassaflöde beräkning'!$C$194:$C$209,'Kassaflöde beräkning'!$A$194:$A$209,"Skatt och AG",'Kassaflöde beräkning'!$E$194:$E$209,">"&$I$3) | E23: =SUMIFS('Kassaflöde beräkning'!$C$194:$C$209,'Kassaflöde beräkning'!$A$194:$A$209,"Skatt och AG",'Kassaflöde beräkning'!$E$194:$E$209,">"&$I$3) | F23: =SUMIFS('Kassaflöde beräkning'!$C$194:$C$209,'Kassaflöde beräkning'!$A$194:$A$209,"Skatt och AG",'Kassaflöde beräkning'!$E$194:$E$209,">"&$I$3) | G23: =SUMIFS('Kassaflöde beräkning'!$C$194:$C$209,'Kassaflöde beräkning'!$A$194:$A$209,"Skatt och AG",'Kassaflöde beräkning'!$E$194:$E$209,">"&$I$3) | H23: =SUMIFS('Kassaflöde beräkning'!$C$194:$C$209,'Kassaflöde beräkning'!$A$194:$A$209,"Skatt och AG",'Kassaflöde beräkning'!$E$194:$E$209,">"&$I$3) | I23: =SUMIFS('Kassaflöde beräkning'!$C$194:$C$209,'Kassaflöde beräkning'!$A$194:$A$209,"Skatt och AG",'Kassaflöde beräkning'!$E$194:$E$209,">"&$I$3)
A24: Moms som förfaller efter december | B24: =IF(MONTH($I$3)=12,IF('Kassaflöde inmatning'!$B$7="Kvartalsvis",SUM(G22:I22),I22),0) | C24: =IF(MONTH($I$3)=12,IF('Kassaflöde inmatning'!$B$7="Kvartalsvis",SUM(G22:I22),I22),0) | D24: =IF(MONTH($I$3)=12,IF('Kassaflöde inmatning'!$B$7="Kvartalsvis",SUM(G22:I22),I22),0) | E24: =IF(MONTH($I$3)=12,IF('Kassaflöde inmatning'!$B$7="Kvartalsvis",SUM(G22:I22),I22),0) | F24: =IF(MONTH($I$3)=12,IF('Kassaflöde inmatning'!$B$7="Kvartalsvis",SUM(G22:I22),I22),0) | G24: =IF(MONTH($I$3)=12,IF('Kassaflöde inmatning'!$B$7="Kvartalsvis",SUM(G22:I22),I22),0) | H24: =IF(MONTH($I$3)=12,IF('Kassaflöde inmatning'!$B$7="Kvartalsvis",SUM(G22:I22),I22),0) | I24: =IF(MONTH($I$3)=12,IF('Kassaflöde inmatning'!$B$7="Kvartalsvis",SUM(G22:I22),I22),0)
A27: Notering | B27: Kundvillkor kan sättas per kund som 30/60 dagar från månadsslut eller fakturadatum. Kostnader kan läggas månadsvis, kvartalsvis, halvårsvis eller årsvis. Lönedatum beräknas som den 25:e eller närmast föregående vardag.

Sheet Kassaflöde beräkning
A1: Beräkningar för kassaflöde
A3: Kund | B3: Fakturamånad | C3: Fakturerat ex moms | D3: Utgående moms | E3: Villkorsdagar | F3: Bas | G3: Förfallodatum | H3: Betalningsmånad
A4: SafeSpring | B4: 46143 | C4: ='Budget maj-dec 2026'!B6 | D4: =IF('Kassaflöde inmatning'!$E$19="Ja",C4*'Kassaflöde inmatning'!$B$6,0) | E4: ='Kassaflöde inmatning'!$C$19 | F4: ='Kassaflöde inmatning'!$D$19 | G4: =IF(F4="Månadsslut",EOMONTH(B4,0)+E4,B4+E4) | H4: =DATE(YEAR(G4),MONTH(G4),1)
A5: SafeSpring | B5: 46174 | C5: ='Budget maj-dec 2026'!C6 | D5: =IF('Kassaflöde inmatning'!$E$19="Ja",C5*'Kassaflöde inmatning'!$B$6,0) | E5: ='Kassaflöde inmatning'!$C$19 | F5: ='Kassaflöde inmatning'!$D$19 | G5: =IF(F5="Månadsslut",EOMONTH(B5,0)+E5,B5+E5) | H5: =DATE(YEAR(G5),MONTH(G5),1)
A6: SafeSpring | B6: 46204 | C6: ='Budget maj-dec 2026'!D6 | D6: =IF('Kassaflöde inmatning'!$E$19="Ja",C6*'Kassaflöde inmatning'!$B$6,0) | E6: ='Kassaflöde inmatning'!$C$19 | F6: ='Kassaflöde inmatning'!$D$19 | G6: =IF(F6="Månadsslut",EOMONTH(B6,0)+E6,B6+E6) | H6: =DATE(YEAR(G6),MONTH(G6),1)
A7: SafeSpring | B7: 46235 | C7: ='Budget maj-dec 2026'!E6 | D7: =IF('Kassaflöde inmatning'!$E$19="Ja",C7*'Kassaflöde inmatning'!$B$6,0) | E7: ='Kassaflöde inmatning'!$C$19 | F7: ='Kassaflöde inmatning'!$D$19 | G7: =IF(F7="Månadsslut",EOMONTH(B7,0)+E7,B7+E7) | H7: =DATE(YEAR(G7),MONTH(G7),1)
A8: SafeSpring | B8: 46266 | C8: ='Budget maj-dec 2026'!F6 | D8: =IF('Kassaflöde inmatning'!$E$19="Ja",C8*'Kassaflöde inmatning'!$B$6,0) | E8: ='Kassaflöde inmatning'!$C$19 | F8: ='Kassaflöde inmatning'!$D$19 | G8: =IF(F8="Månadsslut",EOMONTH(B8,0)+E8,B8+E8) | H8: =DATE(YEAR(G8),MONTH(G8),1)
A9: SafeSpring | B9: 46296 | C9: ='Budget maj-dec 2026'!G6 | D9: =IF('Kassaflöde inmatning'!$E$19="Ja",C9*'Kassaflöde inmatning'!$B$6,0) | E9: ='Kassaflöde inmatning'!$C$19 | F9: ='Kassaflöde inmatning'!$D$19 | G9: =IF(F9="Månadsslut",EOMONTH(B9,0)+E9,B9+E9) | H9: =DATE(YEAR(G9),MONTH(G9),1)
A10: SafeSpring | B10: 46327 | C10: ='Budget maj-dec 2026'!H6 | D10: =IF('Kassaflöde inmatning'!$E$19="Ja",C10*'Kassaflöde inmatning'!$B$6,0) | E10: ='Kassaflöde inmatning'!$C$19 | F10: ='Kassaflöde inmatning'!$D$19 | G10: =IF(F10="Månadsslut",EOMONTH(B10,0)+E10,B10+E10) | H10: =DATE(YEAR(G10),MONTH(G10),1)
A11: SafeSpring | B11: 46357 | C11: ='Budget maj-dec 2026'!I6 | D11: =IF('Kassaflöde inmatning'!$E$19="Ja",C11*'Kassaflöde inmatning'!$B$6,0) | E11: ='Kassaflöde inmatning'!$C$19 | F11: ='Kassaflöde inmatning'!$D$19 | G11: =IF(F11="Månadsslut",EOMONTH(B11,0)+E11,B11+E11) | H11: =DATE(YEAR(G11),MONTH(G11),1)
A12: Accure | B12: 46143 | C12: ='Budget maj-dec 2026'!B7 | D12: =IF('Kassaflöde inmatning'!$E$20="Ja",C12*'Kassaflöde inmatning'!$B$6,0) | E12: ='Kassaflöde inmatning'!$C$20 | F12: ='Kassaflöde inmatning'!$D$20 | G12: =IF(F12="Månadsslut",EOMONTH(B12,0)+E12,B12+E12) | H12: =DATE(YEAR(G12),MONTH(G12),1)
A13: Accure | B13: 46174 | C13: ='Budget maj-dec 2026'!C7 | D13: =IF('Kassaflöde inmatning'!$E$20="Ja",C13*'Kassaflöde inmatning'!$B$6,0) | E13: ='Kassaflöde inmatning'!$C$20 | F13: ='Kassaflöde inmatning'!$D$20 | G13: =IF(F13="Månadsslut",EOMONTH(B13,0)+E13,B13+E13) | H13: =DATE(YEAR(G13),MONTH(G13),1)
A14: Accure | B14: 46204 | C14: ='Budget maj-dec 2026'!D7 | D14: =IF('Kassaflöde inmatning'!$E$20="Ja",C14*'Kassaflöde inmatning'!$B$6,0) | E14: ='Kassaflöde inmatning'!$C$20 | F14: ='Kassaflöde inmatning'!$D$20 | G14: =IF(F14="Månadsslut",EOMONTH(B14,0)+E14,B14+E14) | H14: =DATE(YEAR(G14),MONTH(G14),1)
A15: Accure | B15: 46235 | C15: ='Budget maj-dec 2026'!E7 | D15: =IF('Kassaflöde inmatning'!$E$20="Ja",C15*'Kassaflöde inmatning'!$B$6,0) | E15: ='Kassaflöde inmatning'!$C$20 | F15: ='Kassaflöde inmatning'!$D$20 | G15: =IF(F15="Månadsslut",EOMONTH(B15,0)+E15,B15+E15) | H15: =DATE(YEAR(G15),MONTH(G15),1)
A16: Accure | B16: 46266 | C16: ='Budget maj-dec 2026'!F7 | D16: =IF('Kassaflöde inmatning'!$E$20="Ja",C16*'Kassaflöde inmatning'!$B$6,0) | E16: ='Kassaflöde inmatning'!$C$20 | F16: ='Kassaflöde inmatning'!$D$20 | G16: =IF(F16="Månadsslut",EOMONTH(B16,0)+E16,B16+E16) | H16: =DATE(YEAR(G16),MONTH(G16),1)
A17: Accure | B17: 46296 | C17: ='Budget maj-dec 2026'!G7 | D17: =IF('Kassaflöde inmatning'!$E$20="Ja",C17*'Kassaflöde inmatning'!$B$6,0) | E17: ='Kassaflöde inmatning'!$C$20 | F17: ='Kassaflöde inmatning'!$D$20 | G17: =IF(F17="Månadsslut",EOMONTH(B17,0)+E17,B17+E17) | H17: =DATE(YEAR(G17),MONTH(G17),1)
A18: Accure | B18: 46327 | C18: ='Budget maj-dec 2026'!H7 | D18: =IF('Kassaflöde inmatning'!$E$20="Ja",C18*'Kassaflöde inmatning'!$B$6,0) | E18: ='Kassaflöde inmatning'!$C$20 | F18: ='Kassaflöde inmatning'!$D$20 | G18: =IF(F18="Månadsslut",EOMONTH(B18,0)+E18,B18+E18) | H18: =DATE(YEAR(G18),MONTH(G18),1)
A19: Accure | B19: 46357 | C19: ='Budget maj-dec 2026'!I7 | D19: =IF('Kassaflöde inmatning'!$E$20="Ja",C19*'Kassaflöde inmatning'!$B$6,0) | E19: ='Kassaflöde inmatning'!$C$20 | F19: ='Kassaflöde inmatning'!$D$20 | G19: =IF(F19="Månadsslut",EOMONTH(B19,0)+E19,B19+E19) | H19: =DATE(YEAR(G19),MONTH(G19),1)
A20: Team Neusta | B20: 46143 | C20: ='Budget maj-dec 2026'!B8 | D20: =IF('Kassaflöde inmatning'!$E$21="Ja",C20*'Kassaflöde inmatning'!$B$6,0) | E20: ='Kassaflöde inmatning'!$C$21 | F20: ='Kassaflöde inmatning'!$D$21 | G20: =IF(F20="Månadsslut",EOMONTH(B20,0)+E20,B20+E20) | H20: =DATE(YEAR(G20),MONTH(G20),1)
A21: Team Neusta | B21: 46174 | C21: ='Budget maj-dec 2026'!C8 | D21: =IF('Kassaflöde inmatning'!$E$21="Ja",C21*'Kassaflöde inmatning'!$B$6,0) | E21: ='Kassaflöde inmatning'!$C$21 | F21: ='Kassaflöde inmatning'!$D$21 | G21: =IF(F21="Månadsslut",EOMONTH(B21,0)+E21,B21+E21) | H21: =DATE(YEAR(G21),MONTH(G21),1)
A22: Team Neusta | B22: 46204 | C22: ='Budget maj-dec 2026'!D8 | D22: =IF('Kassaflöde inmatning'!$E$21="Ja",C22*'Kassaflöde inmatning'!$B$6,0) | E22: ='Kassaflöde inmatning'!$C$21 | F22: ='Kassaflöde inmatning'!$D$21 | G22: =IF(F22="Månadsslut",EOMONTH(B22,0)+E22,B22+E22) | H22: =DATE(YEAR(G22),MONTH(G22),1)
A23: Team Neusta | B23: 46235 | C23: ='Budget maj-dec 2026'!E8 | D23: =IF('Kassaflöde inmatning'!$E$21="Ja",C23*'Kassaflöde inmatning'!$B$6,0) | E23: ='Kassaflöde inmatning'!$C$21 | F23: ='Kassaflöde inmatning'!$D$21 | G23: =IF(F23="Månadsslut",EOMONTH(B23,0)+E23,B23+E23) | H23: =DATE(YEAR(G23),MONTH(G23),1)
A24: Team Neusta | B24: 46266 | C24: ='Budget maj-dec 2026'!F8 | D24: =IF('Kassaflöde inmatning'!$E$21="Ja",C24*'Kassaflöde inmatning'!$B$6,0) | E24: ='Kassaflöde inmatning'!$C$21 | F24: ='Kassaflöde inmatning'!$D$21 | G24: =IF(F24="Månadsslut",EOMONTH(B24,0)+E24,B24+E24) | H24: =DATE(YEAR(G24),MONTH(G24),1)
A25: Team Neusta | B25: 46296 | C25: ='Budget maj-dec 2026'!G8 | D25: =IF('Kassaflöde inmatning'!$E$21="Ja",C25*'Kassaflöde inmatning'!$B$6,0) | E25: ='Kassaflöde inmatning'!$C$21 | F25: ='Kassaflöde inmatning'!$D$21 | G25: =IF(F25="Månadsslut",EOMONTH(B25,0)+E25,B25+E25) | H25: =DATE(YEAR(G25),MONTH(G25),1)
A26: Team Neusta | B26: 46327 | C26: ='Budget maj-dec 2026'!H8 | D26: =IF('Kassaflöde inmatning'!$E$21="Ja",C26*'Kassaflöde inmatning'!$B$6,0) | E26: ='Kassaflöde inmatning'!$C$21 | F26: ='Kassaflöde inmatning'!$D$21 | G26: =IF(F26="Månadsslut",EOMONTH(B26,0)+E26,B26+E26) | H26: =DATE(YEAR(G26),MONTH(G26),1)
A27: Team Neusta | B27: 46357 | C27: ='Budget maj-dec 2026'!I8 | D27: =IF('Kassaflöde inmatning'!$E$21="Ja",C27*'Kassaflöde inmatning'!$B$6,0) | E27: ='Kassaflöde inmatning'!$C$21 | F27: ='Kassaflöde inmatning'!$D$21 | G27: =IF(F27="Månadsslut",EOMONTH(B27,0)+E27,B27+E27) | H27: =DATE(YEAR(G27),MONTH(G27),1)
A28: Volvo Energy | B28: 46143 | C28: ='Budget maj-dec 2026'!B9 | D28: =IF('Kassaflöde inmatning'!$E$22="Ja",C28*'Kassaflöde inmatning'!$B$6,0) | E28: ='Kassaflöde inmatning'!$C$22 | F28: ='Kassaflöde inmatning'!$D$22 | G28: =IF(F28="Månadsslut",EOMONTH(B28,0)+E28,B28+E28) | H28: =DATE(YEAR(G28),MONTH(G28),1)
A29: Volvo Energy | B29: 46174 | C29: ='Budget maj-dec 2026'!C9 | D29: =IF('Kassaflöde inmatning'!$E$22="Ja",C29*'Kassaflöde inmatning'!$B$6,0) | E29: ='Kassaflöde inmatning'!$C$22 | F29: ='Kassaflöde inmatning'!$D$22 | G29: =IF(F29="Månadsslut",EOMONTH(B29,0)+E29,B29+E29) | H29: =DATE(YEAR(G29),MONTH(G29),1)
A30: Volvo Energy | B30: 46204 | C30: ='Budget maj-dec 2026'!D9 | D30: =IF('Kassaflöde inmatning'!$E$22="Ja",C30*'Kassaflöde inmatning'!$B$6,0) | E30: ='Kassaflöde inmatning'!$C$22 | F30: ='Kassaflöde inmatning'!$D$22 | G30: =IF(F30="Månadsslut",EOMONTH(B30,0)+E30,B30+E30) | H30: =DATE(YEAR(G30),MONTH(G30),1)
A31: Volvo Energy | B31: 46235 | C31: ='Budget maj-dec 2026'!E9 | D31: =IF('Kassaflöde inmatning'!$E$22="Ja",C31*'Kassaflöde inmatning'!$B$6,0) | E31: ='Kassaflöde inmatning'!$C$22 | F31: ='Kassaflöde inmatning'!$D$22 | G31: =IF(F31="Månadsslut",EOMONTH(B31,0)+E31,B31+E31) | H31: =DATE(YEAR(G31),MONTH(G31),1)
A32: Volvo Energy | B32: 46266 | C32: ='Budget maj-dec 2026'!F9 | D32: =IF('Kassaflöde inmatning'!$E$22="Ja",C32*'Kassaflöde inmatning'!$B$6,0) | E32: ='Kassaflöde inmatning'!$C$22 | F32: ='Kassaflöde inmatning'!$D$22 | G32: =IF(F32="Månadsslut",EOMONTH(B32,0)+E32,B32+E32) | H32: =DATE(YEAR(G32),MONTH(G32),1)
A33: Volvo Energy | B33: 46296 | C33: ='Budget maj-dec 2026'!G9 | D33: =IF('Kassaflöde inmatning'!$E$22="Ja",C33*'Kassaflöde inmatning'!$B$6,0) | E33: ='Kassaflöde inmatning'!$C$22 | F33: ='Kassaflöde inmatning'!$D$22 | G33: =IF(F33="Månadsslut",EOMONTH(B33,0)+E33,B33+E33) | H33: =DATE(YEAR(G33),MONTH(G33),1)
A34: Volvo Energy | B34: 46327 | C34: ='Budget maj-dec 2026'!H9 | D34: =IF('Kassaflöde inmatning'!$E$22="Ja",C34*'Kassaflöde inmatning'!$B$6,0) | E34: ='Kassaflöde inmatning'!$C$22 | F34: ='Kassaflöde inmatning'!$D$22 | G34: =IF(F34="Månadsslut",EOMONTH(B34,0)+E34,B34+E34) | H34: =DATE(YEAR(G34),MONTH(G34),1)
A35: Volvo Energy | B35: 46357 | C35: ='Budget maj-dec 2026'!I9 | D35: =IF('Kassaflöde inmatning'!$E$22="Ja",C35*'Kassaflöde inmatning'!$B$6,0) | E35: ='Kassaflöde inmatning'!$C$22 | F35: ='Kassaflöde inmatning'!$D$22 | G35: =IF(F35="Månadsslut",EOMONTH(B35,0)+E35,B35+E35) | H35: =DATE(YEAR(G35),MONTH(G35),1)
A36: Buddy Energy | B36: 46143 | C36: ='Budget maj-dec 2026'!B10 | D36: =IF('Kassaflöde inmatning'!$E$23="Ja",C36*'Kassaflöde inmatning'!$B$6,0) | E36: ='Kassaflöde inmatning'!$C$23 | F36: ='Kassaflöde inmatning'!$D$23 | G36: =IF(F36="Månadsslut",EOMONTH(B36,0)+E36,B36+E36) | H36: =DATE(YEAR(G36),MONTH(G36),1)
A37: Buddy Energy | B37: 46174 | C37: ='Budget maj-dec 2026'!C10 | D37: =IF('Kassaflöde inmatning'!$E$23="Ja",C37*'Kassaflöde inmatning'!$B$6,0) | E37: ='Kassaflöde inmatning'!$C$23 | F37: ='Kassaflöde inmatning'!$D$23 | G37: =IF(F37="Månadsslut",EOMONTH(B37,0)+E37,B37+E37) | H37: =DATE(YEAR(G37),MONTH(G37),1)
A38: Buddy Energy | B38: 46204 | C38: ='Budget maj-dec 2026'!D10 | D38: =IF('Kassaflöde inmatning'!$E$23="Ja",C38*'Kassaflöde inmatning'!$B$6,0) | E38: ='Kassaflöde inmatning'!$C$23 | F38: ='Kassaflöde inmatning'!$D$23 | G38: =IF(F38="Månadsslut",EOMONTH(B38,0)+E38,B38+E38) | H38: =DATE(YEAR(G38),MONTH(G38),1)
A39: Buddy Energy | B39: 46235 | C39: ='Budget maj-dec 2026'!E10 | D39: =IF('Kassaflöde inmatning'!$E$23="Ja",C39*'Kassaflöde inmatning'!$B$6,0) | E39: ='Kassaflöde inmatning'!$C$23 | F39: ='Kassaflöde inmatning'!$D$23 | G39: =IF(F39="Månadsslut",EOMONTH(B39,0)+E39,B39+E39) | H39: =DATE(YEAR(G39),MONTH(G39),1)
A40: Buddy Energy | B40: 46266 | C40: ='Budget maj-dec 2026'!F10 | D40: =IF('Kassaflöde inmatning'!$E$23="Ja",C40*'Kassaflöde inmatning'!$B$6,0) | E40: ='Kassaflöde inmatning'!$C$23 | F40: ='Kassaflöde inmatning'!$D$23 | G40: =IF(F40="Månadsslut",EOMONTH(B40,0)+E40,B40+E40) | H40: =DATE(YEAR(G40),MONTH(G40),1)
A41: Buddy Energy | B41: 46296 | C41: ='Budget maj-dec 2026'!G10 | D41: =IF('Kassaflöde inmatning'!$E$23="Ja",C41*'Kassaflöde inmatning'!$B$6,0) | E41: ='Kassaflöde inmatning'!$C$23 | F41: ='Kassaflöde inmatning'!$D$23 | G41: =IF(F41="Månadsslut",EOMONTH(B41,0)+E41,B41+E41) | H41: =DATE(YEAR(G41),MONTH(G41),1)
...

Sheet Resultat
A1: Post | B1: Belopp (kr)
A2: PERSONAL (per månad)
A3: Bruttolöner | B3: =SUM('Inmatning'!B42:B47)
A4: Arbetsgivaravgifter | B4: =B3*'Inmatning'!B4
A5: Tjänstepension | B5: =SUMPRODUCT('Inmatning'!B42:B47,'Inmatning'!C42:C47)
A6: Personalförsäkringar | B6: =B3*'Inmatning'!B6
A7: Summa personal/mån | B7: =SUM(B3:B6)
A9: ABONNEMANG & MJUKVARA (per månad)
A10: Företagsförsäkring | B10: {='Inmatning'!B7}
A11: Mobilabonnemang | B11: {='Inmatning'!B8*'Inmatning'!B9}
A12: Internet (kontor) | B12: {='Inmatning'!B10}
A13: Microsoft 365 | B13: {='Inmatning'!B11*'Inmatning'!B12}
A14: Adobe Creative Cloud | B14: {='Inmatning'!B13*'Inmatning'!B14}
A15: E-signering | B15: {='Inmatning'!B15}
A16: Bokföring/Fakturering | B16: {='Inmatning'!B16}
A17: Projektstyrning | B17: {='Inmatning'!B17}
A18: Summa abonnemang & mjukvara/mån | B18: {=SUM(B10:B17)}
A20: LOKAL & DRIFT (per månad)
A21: Förbrukning/kaffe/print/städ | B21: {='Inmatning'!B18}
A22: Kontorshyra | B22: {='Inmatning'!B19}
A23: Summa lokal & drift/mån | B23: {=SUM(B21:B22)}
A25: SUBTOTAL OPEX (exkl. hyra) | B25: {=B7+B18+B21}
A26: Månadskostnad inkl. hyra (OPEX) | B26: {=B7+B18+B23}
A27: Årskostnad inkl. hyra (OPEX × 12) | B27: {=B26*12}
A29: CAPEX – Hårdvara & kontorsutrustning (engångs)
A30: Bärbara datorer | B30: {='Inmatning'!B20*'Inmatning'!B2}
A31: Skärmar 27" | B31: {='Inmatning'!B21*'Inmatning'!B2}
A32: Dockor | B32: {='Inmatning'!B22*'Inmatning'!B2}
A33: Tangentbord/mus | B33: {='Inmatning'!B23*'Inmatning'!B2}
A34: Mobiltelefoner | B34: {='Inmatning'!B24*'Inmatning'!B2}
A35: Skrivbord + stolar | B35: {='Inmatning'!B25*'Inmatning'!B2}
A36: Mötesbord/stolar | B36: {='Inmatning'!B26}
A37: Skrivare | B37: {='Inmatning'!B27}
A38: Smått & övrigt | B38: {='Inmatning'!B28}
A39: Summa CAPEX | B39: {=SUM(B30:B38)}
A40: Avskrivning (mån) | B40: {=B39/'Inmatning'!B29}
A42: All-in månad (OPEX inkl. hyra + avskrivning) | B42: {=B26+B40}
A43: Kostnad per person och månad | B43: {=B26/'Inmatning'!B2}
A44: Debiterbara timmar/pers/mån | B44: {='Inmatning'!B30*'Inmatning'!B31}
A45: Intern kostnad per debiterbar timme | B45: {=B26/('Inmatning'!B2*B44)}
...

Sheet Hjälptabell
A1: Månad | B1: Resultat P&L | C1: Ack. resultat P&L | D1: Kassaflöde | E1: Ack. kassaflöde
A2: Maj | B2: {='Budget maj-dec 2026'!B17-SUM('Budget maj-dec 2026'!B66,'Budget maj-dec 2026'!B79,'Budget maj-dec 2026'!B84,'Budget maj-dec 2026'!B87)} | C2: {=B2} | D2: {='Budget maj-dec 2026'!B17-SUM('Budget maj-dec 2026'!B66,'Budget maj-dec 2026'!B79,'Budget maj-dec 2026'!B84,'Budget maj-dec 2026'!B87)+'Budget maj-dec 2026'!B87-'Budget maj-dec 2026'!B88} | E2: {=D2}
A3: Juni | B3: {='Budget maj-dec 2026'!C17-SUM('Budget maj-dec 2026'!C66,'Budget maj-dec 2026'!C79,'Budget maj-dec 2026'!C84,'Budget maj-dec 2026'!C87)} | C3: {=C2+B3} | D3: {='Budget maj-dec 2026'!C17-SUM('Budget maj-dec 2026'!C66,'Budget maj-dec 2026'!C79,'Budget maj-dec 2026'!C84,'Budget maj-dec 2026'!C87)+'Budget maj-dec 2026'!C87-'Budget maj-dec 2026'!C88} | E3: {=E2+D3}
A4: Juli | B4: {='Budget maj-dec 2026'!D17-SUM('Budget maj-dec 2026'!D66,'Budget maj-dec 2026'!D79,'Budget maj-dec 2026'!D84,'Budget maj-dec 2026'!D87)} | C4: {=C3+B4} | D4: {='Budget maj-dec 2026'!D17-SUM('Budget maj-dec 2026'!D66,'Budget maj-dec 2026'!D79,'Budget maj-dec 2026'!D84,'Budget maj-dec 2026'!D87)+'Budget maj-dec 2026'!D87-'Budget maj-dec 2026'!D88} | E4: {=E3+D4}
A5: Augusti | B5: {='Budget maj-dec 2026'!E17-SUM('Budget maj-dec 2026'!E66,'Budget maj-dec 2026'!E79,'Budget maj-dec 2026'!E84,'Budget maj-dec 2026'!E87)} | C5: {=C4+B5} | D5: {='Budget maj-dec 2026'!E17-SUM('Budget maj-dec 2026'!E66,'Budget maj-dec 2026'!E79,'Budget maj-dec 2026'!E84,'Budget maj-dec 2026'!E87)+'Budget maj-dec 2026'!E87-'Budget maj-dec 2026'!E88} | E5: {=E4+D5}
A6: September | B6: {='Budget maj-dec 2026'!F17-SUM('Budget maj-dec 2026'!F66,'Budget maj-dec 2026'!F79,'Budget maj-dec 2026'!F84,'Budget maj-dec 2026'!F87)} | C6: {=C5+B6} | D6: {='Budget maj-dec 2026'!F17-SUM('Budget maj-dec 2026'!F66,'Budget maj-dec 2026'!F79,'Budget maj-dec 2026'!F84,'Budget maj-dec 2026'!F87)+'Budget maj-dec 2026'!F87-'Budget maj-dec 2026'!F88} | E6: {=E5+D6}
A7: Oktober | B7: {='Budget maj-dec 2026'!G17-SUM('Budget maj-dec 2026'!G66,'Budget maj-dec 2026'!G79,'Budget maj-dec 2026'!G84,'Budget maj-dec 2026'!G87)} | C7: {=C6+B7} | D7: {='Budget maj-dec 2026'!G17-SUM('Budget maj-dec 2026'!G66,'Budget maj-dec 2026'!G79,'Budget maj-dec 2026'!G84,'Budget maj-dec 2026'!G87)+'Budget maj-dec 2026'!G87-'Budget maj-dec 2026'!G88} | E7: {=E6+D7}
A8: November | B8: {='Budget maj-dec 2026'!H17-SUM('Budget maj-dec 2026'!H66,'Budget maj-dec 2026'!H79,'Budget maj-dec 2026'!H84,'Budget maj-dec 2026'!H87)} | C8: {=C7+B8} | D8: {='Budget maj-dec 2026'!H17-SUM('Budget maj-dec 2026'!H66,'Budget maj-dec 2026'!H79,'Budget maj-dec 2026'!H84,'Budget maj-dec 2026'!H87)+'Budget maj-dec 2026'!H87-'Budget maj-dec 2026'!H88} | E8: {=E7+D8}
A9: December | B9: {='Budget maj-dec 2026'!I17-SUM('Budget maj-dec 2026'!I66,'Budget maj-dec 2026'!I79,'Budget maj-dec 2026'!I84,'Budget maj-dec 2026'!I87)} | C9: {=C8+B9} | D9: {='Budget maj-dec 2026'!I17-SUM('Budget maj-dec 2026'!I66,'Budget maj-dec 2026'!I79,'Budget maj-dec 2026'!I84,'Budget maj-dec 2026'!I87)+'Budget maj-dec 2026'!I87-'Budget maj-dec 2026'!I88} | E9: {=E8+D9}
